Workbook
Name CAR_BEDS: Inputs!$B$5
Name CAR_CAP: Inputs!$C$5
Name CAR_DIM: Inputs!$G$5
Name CAR_FERT: Inputs!$F$5
Name CAR_HRS: Inputs!$E$5
Name FIXED_COST: Inputs!$B$11
Name HOURS_PER_WEEK: Inputs!$B$18
Name MAX_TEMP_WORKERS: Inputs!$B$17
Name MES_BEDS: Inputs!$B$6
Name MES_CAP: Inputs!$C$6
Name MES_DIM: Inputs!$G$6
Name MES_FERT: Inputs!$F$6
Name MES_HRS: Inputs!$E$6
Name MES_PRICE: Inputs!$D$6
Name OWNER_ANNUAL_VALUE: Inputs!$B$20
Name OWNER_FIELD_SHARE: Inputs!$B$19
Name OWNER_HRS: Inputs!$B$13
Name OWNER_RATE: Inputs!$B$14
Name TEMP_ANNUAL_VALUE: Inputs!$B$21
Name TEMP_HRS_PER_WORKER: Inputs!$B$16
Name TEMP_RATE: Inputs!$B$15
Name TOM_BEDS: Inputs!$B$4
Name TOM_CAP: Inputs!$C$4
Name TOM_DIM: Inputs!$G$4
Name TOM_HRS: Inputs!$E$4
Name TOM_PRICE: Inputs!$D$4
Name TOTAL_BEDS: Inputs!$B$12
Name WEEKS: Inputs!$B$10

Sheet Inputs
A1: FARM MODEL | INPUTS
A3: Crop | B3: Beds (editable) | C3: Cap | D3: Revenue / bed ($) | E3: Field hrs / wk / bed | F3: Fertilizer / bed ($) | G3: Diminishing rate | I3: SINGLE-SHEET SOLVER SETUP | J3: Calculated value
A4: Tomatoes | B4: 10.004049 | C4: 20 | D4: 8800 | E4: 2.5 | F4: 880 | G4: 0.1 | I4: Season profit | J4: ='Cost Structure'!B19 -> 42761.674
A5: Carrots | B5: 20 | C5: 20 | D5: 2094 | E5: =2.5/3 -> 0.83333333 | F5: 440 | G5: 0.025 | I5: Total beds used | J5: ='Cost Structure'!B8 -> 60.004049
A6: Mesclun | B6: 30 | C6: 30 | D6: 2700 | E6: 1.25 | F6: 880 | G6: 0.0125 | I6: Total labor hours | J6: ='Cost Structure'!B11 -> 5279.0627
I7: Temporary labor hours | J7: ='Cost Structure'!B13 -> 4559.0627
I8: Maximum beds | J8: =B12 -> 64
I9: Maximum labor hours | J9: ='Cost Structure'!B20 -> 6480
A10: Season weeks | B10: 36 | I10: Maximum temporary hours | J10: =B16*B17 -> 5760
A11: Fixed cost ($) | B11: 20000
A12: Available beds | B12: 64 | I12: SOLVER SETTINGS
A13: Owner hours | B13: =B18*B10*B19 -> 720 | I13: Set Objective (Max) | J13: $J$4
A14: Owner hourly rate ($) | B14: =B20/(B18*B10) -> 34.722222 | I14: Changing cells | J14: $B$4:$B$6
A15: Temp hourly rate ($) | B15: =B21/(B18*B10) -> 17.361111 | I15: Solving method | J15: GRG Nonlinear
A16: Temp hours / worker | B16: =B18*B10 -> 1440 | I16: Run starts | J16: 0/0/0, then 20/0/0
A17: Maximum temp workers | B17: 4
A18: Hours per week | B18: 40 | I18: CONSTRAINTS (all on Inputs)
A19: Owner field share | B19: 0.5 | I19: $B$4 <= $C$4 | J19: Tomato cap
A20: Owner annual value ($) | B20: 50000 | I20: $B$5 <= $C$5 | J20: Carrot cap
A21: Temp annual value ($) | B21: 25000 | I21: $B$6 <= $C$6 | J21: Mesclun cap
I22: $B$4:$B$6 = int | J22: Whole beds
A23: Source | B23: https://adamwstauffer.github.io/ai-lms/case-perfect-competition.html | I23: $B$4:$B$6 >= 0 | J23: Nonnegative
I24: $J$5 <= $J$8 | J24: 64-bed limit
A25: Blue cells are editable case inputs; start with original hypothesis. | I25: $J$6 <= $J$9 | J25: Labor limit
I26: $J$7 <= $J$10 | J26: Temporary labor limit

Sheet Cost Structure
A1: FARM MODEL | COST STRUCTURE
A3: Crop | B3: Beds | C3: Revenue ($) | D3: Fertilizer ($) | E3: Labor hours | F3: Allocated labor ($)
A4: Tomatoes | B4: =Inputs!B4 -> 10.004049 | C4: =B4*Inputs!D4 -> 88035.631 | D4: =B4*Inputs!F4 -> 8803.5631 | E4: =B4*Inputs!E4*Inputs!$B$10*(1+Inputs!G4)^B4 -> 2336.2148 | F4: =E4*$B$17 -> 46091.078
A5: Carrots | B5: =Inputs!B5 -> 20 | C5: =B5*Inputs!D5 -> 41880 | D5: =B5*Inputs!F5 -> 8800 | E5: =B5*Inputs!E5*Inputs!$B$10*(1+Inputs!G5)^B5 -> 983.16986 | F5: =E5*$B$17 -> 19396.915
A6: Mesclun | B6: =Inputs!B6 -> 30 | C6: =B6*Inputs!D6 -> 81000 | D6: =B6*Inputs!F6 -> 26400 | E6: =B6*Inputs!E6*Inputs!$B$10*(1+Inputs!G6)^B6 -> 1959.678 | F6: =E6*$B$17 -> 38662.401
A8: Total beds | B8: =SUM(B4:B6) -> 60.004049
A9: Total revenue ($) | B9: =SUM(C4:C6) -> 210915.63
A10: Total fertilizer ($) | B10: =SUM(D4:D6) -> 44003.563
A11: Total labor hours | B11: =SUM(E4:E6) -> 5279.0627
A12: Owner hours used | B12: =MIN(B11,Inputs!B13) -> 720
A13: Temporary hours used | B13: =MAX(0,B11-B12) -> 4559.0627
A14: Owner labor cost ($) | B14: =B12*Inputs!B14 -> 25000
A15: Temporary labor cost ($) | B15: =B13*Inputs!B15 -> 79150.394
A16: Total labor cost ($) | B16: =B14+B15 -> 104150.39
A17: Blended labor rate ($/hr) | B17: =IF(B11=0,0,B16/B11) -> 19.728956
A18: Fixed cost ($) | B18: =Inputs!B11 -> 20000
A19: Season profit ($) | B19: =B9-B10-B16-B18 -> 42761.674
A20: Labor hours available | B20: =Inputs!B13+Inputs!B16*Inputs!B17 -> 6480
A21: Labor capacity remaining | B21: =B20-B11 -> 1200.9373
A22: Unused beds | B22: =Inputs!B12-B8 -> 3.995951
A23: Temp workers equivalent | B23: =B13/Inputs!B16 -> 3.1660158
A24: Allocated labor reconciliation | B24: =SUM(F4:F6)-B16 -> 0

Sheet Marginal Cost
A1: FARM MODEL | MARGINAL COST
A3: Crop | B3: Beds | C3: Labor hrs | D3: Revenue ($) | E3: Fertilizer ($) | F3: Labor cost ($) | G3: Marginal cost ($) | H3: Price minus MC ($)
A4: Tomatoes | B4: 0 | C4: =B4*Inputs!E4*Inputs!$B$10*(1+Inputs!G4)^B4 -> 0 | D4: =B4*Inputs!D4 -> 0 | E4: =B4*Inputs!F4 -> 0 | F4: =MIN(C4,Inputs!$B$13)*Inputs!$B$14+MAX(0,C4-Inputs!$B$13)*Inputs!$B$15 -> 0
A5: Tomatoes | B5: 1 | C5: =B5*Inputs!E4*Inputs!$B$10*(1+Inputs!G4)^B5 -> 99 | D5: =B5*Inputs!D4 -> 8800 | E5: =B5*Inputs!F4 -> 880 | F5: =MIN(C5,Inputs!$B$13)*Inputs!$B$14+MAX(0,C5-Inputs!$B$13)*Inputs!$B$15 -> 3437.5 | G5: =E5+F5-E4-F4 -> 4317.5 | H5: =Inputs!D4-G5 -> 4482.5
A6: Tomatoes | B6: 2 | C6: =B6*Inputs!E4*Inputs!$B$10*(1+Inputs!G4)^B6 -> 217.8 | D6: =B6*Inputs!D4 -> 17600 | E6: =B6*Inputs!F4 -> 1760 | F6: =MIN(C6,Inputs!$B$13)*Inputs!$B$14+MAX(0,C6-Inputs!$B$13)*Inputs!$B$15 -> 7562.5 | G6: =E6+F6-E5-F5 -> 5005 | H6: =Inputs!D4-G6 -> 3795
A7: Tomatoes | B7: 3 | C7: =B7*Inputs!E4*Inputs!$B$10*(1+Inputs!G4)^B7 -> 359.37 | D7: =B7*Inputs!D4 -> 26400 | E7: =B7*Inputs!F4 -> 2640 | F7: =MIN(C7,Inputs!$B$13)*Inputs!$B$14+MAX(0,C7-Inputs!$B$13)*Inputs!$B$15 -> 12478.125 | G7: =E7+F7-E6-F6 -> 5795.625 | H7: =Inputs!D4-G7 -> 3004.375
A8: Tomatoes | B8: 4 | C8: =B8*Inputs!E4*Inputs!$B$10*(1+Inputs!G4)^B8 -> 527.076 | D8: =B8*Inputs!D4 -> 35200 | E8: =B8*Inputs!F4 -> 3520 | F8: =MIN(C8,Inputs!$B$13)*Inputs!$B$14+MAX(0,C8-Inputs!$B$13)*Inputs!$B$15 -> 18301.25 | G8: =E8+F8-E7-F7 -> 6703.125 | H8: =Inputs!D4-G8 -> 2096.875
A9: Tomatoes | B9: 5 | C9: =B9*Inputs!E4*Inputs!$B$10*(1+Inputs!G4)^B9 -> 724.7295 | D9: =B9*Inputs!D4 -> 44000 | E9: =B9*Inputs!F4 -> 4400 | F9: =MIN(C9,Inputs!$B$13)*Inputs!$B$14+MAX(0,C9-Inputs!$B$13)*Inputs!$B$15 -> 25082.109 | G9: =E9+F9-E8-F8 -> 7660.8594 | H9: =Inputs!D4-G9 -> 1139.1406
A10: Tomatoes | B10: 6 | C10: =B10*Inputs!E4*Inputs!$B$10*(1+Inputs!G4)^B10 -> 956.64294 | D10: =B10*Inputs!D4 -> 52800 | E10: =B10*Inputs!F4 -> 5280 | F10: =MIN(C10,Inputs!$B$13)*Inputs!$B$14+MAX(0,C10-Inputs!$B$13)*Inputs!$B$15 -> 29108.384 | G10: =E10+F10-E9-F9 -> 4906.275 | H10: =Inputs!D4-G10 -> 3893.725
A11: Tomatoes | B11: 7 | C11: =B11*Inputs!E4*Inputs!$B$10*(1+Inputs!G4)^B11 -> 1227.6918 | D11: =B11*Inputs!D4 -> 61600 | E11: =B11*Inputs!F4 -> 6160 | F11: =MIN(C11,Inputs!$B$13)*Inputs!$B$14+MAX(0,C11-Inputs!$B$13)*Inputs!$B$15 -> 33814.093 | G11: =E11+F11-E10-F10 -> 5585.7089 | H11: =Inputs!D4-G11 -> 3214.2911
A12: Tomatoes | B12: 8 | C12: =B12*Inputs!E4*Inputs!$B$10*(1+Inputs!G4)^B12 -> 1543.3839 | D12: =B12*Inputs!D4 -> 70400 | E12: =B12*Inputs!F4 -> 7040 | F12: =MIN(C12,Inputs!$B$13)*Inputs!$B$14+MAX(0,C12-Inputs!$B$13)*Inputs!$B$15 -> 39294.86 | G12: =E12+F12-E11-F11 -> 6360.7668 | H12: =Inputs!D4-G12 -> 2439.2332
A13: Tomatoes | B13: 9 | C13: =B13*Inputs!E4*Inputs!$B$10*(1+Inputs!G4)^B13 -> 1909.9376 | D13: =B13*Inputs!D4 -> 79200 | E13: =B13*Inputs!F4 -> 7920 | F13: =MIN(C13,Inputs!$B$13)*Inputs!$B$14+MAX(0,C13-Inputs!$B$13)*Inputs!$B$15 -> 45658.639 | G13: =E13+F13-E12-F12 -> 7243.7793 | H13: =Inputs!D4-G13 -> 1556.2207
A14: Tomatoes | B14: 10 | C14: =B14*Inputs!E4*Inputs!$B$10*(1+Inputs!G4)^B14 -> 2334.3682 | D14: =B14*Inputs!D4 -> 88000 | E14: =B14*Inputs!F4 -> 8800 | F14: =MIN(C14,Inputs!$B$13)*Inputs!$B$14+MAX(0,C14-Inputs!$B$13)*Inputs!$B$15 -> 53027.226 | G14: =E14+F14-E13-F13 -> 8248.5865 | H14: =Inputs!D4-G14 -> 551.41347
A15: Tomatoes | B15: 11 | C15: =B15*Inputs!E4*Inputs!$B$10*(1+Inputs!G4)^B15 -> 2824.5855 | D15: =B15*Inputs!D4 -> 96800 | E15: =B15*Inputs!F4 -> 9680 | F15: =MIN(C15,Inputs!$B$13)*Inputs!$B$14+MAX(0,C15-Inputs!$B$13)*Inputs!$B$15 -> 61537.943 | G15: =E15+F15-E14-F14 -> 9390.7174 | H15: =Inputs!D4-G15 -> -590.71745
A16: Tomatoes | B16: 12 | C16: =B16*Inputs!E4*Inputs!$B$10*(1+Inputs!G4)^B16 -> 3389.5026 | D16: =B16*Inputs!D4 -> 105600 | E16: =B16*Inputs!F4 -> 10560 | F16: =MIN(C16,Inputs!$B$13)*Inputs!$B$14+MAX(0,C16-Inputs!$B$13)*Inputs!$B$15 -> 71345.532 | G16: =E16+F16-E15-F15 -> 10687.589 | H16: =Inputs!D4-G16 -> -1887.5887
A17: Tomatoes | B17: 13 | C17: =B17*Inputs!E4*Inputs!$B$10*(1+Inputs!G4)^B17 -> 4039.1573 | D17: =B17*Inputs!D4 -> 114400 | E17: =B17*Inputs!F4 -> 11440 | F17: =MIN(C17,Inputs!$B$13)*Inputs!$B$14+MAX(0,C17-Inputs!$B$13)*Inputs!$B$15 -> 82624.259 | G17: =E17+F17-E16-F16 -> 12158.727 | H17: =Inputs!D4-G17 -> -3358.727
A18: Tomatoes | B18: 14 | C18: =B18*Inputs!E4*Inputs!$B$10*(1+Inputs!G4)^B18 -> 4784.8479 | D18: =B18*Inputs!D4 -> 123200 | E18: =B18*Inputs!F4 -> 12320 | F18: =MIN(C18,Inputs!$B$13)*Inputs!$B$14+MAX(0,C18-Inputs!$B$13)*Inputs!$B$15 -> 95570.276 | G18: =E18+F18-E17-F17 -> 13826.017 | H18: =Inputs!D4-G18 -> -5026.0171
A19: Tomatoes | B19: 15 | C19: =B19*Inputs!E4*Inputs!$B$10*(1+Inputs!G4)^B19 -> 5639.285 | D19: =B19*Inputs!D4 -> 132000 | E19: =B19*Inputs!F4 -> 13200 | F19: =MIN(C19,Inputs!$B$13)*Inputs!$B$14+MAX(0,C19-Inputs!$B$13)*Inputs!$B$15 -> 110404.25 | G19: =E19+F19-E18-F18 -> 15713.978 | H19: =Inputs!D4-G19 -> -6913.9779
A20: Tomatoes | B20: 16 | C20: =B20*Inputs!E4*Inputs!$B$10*(1+Inputs!G4)^B20 -> 6616.7611 | D20: =B20*Inputs!D4 -> 140800 | E20: =B20*Inputs!F4 -> 14080 | F20: =MIN(C20,Inputs!$B$13)*Inputs!$B$14+MAX(0,C20-Inputs!$B$13)*Inputs!$B$15 -> 127374.32 | G20: =E20+F20-E19-F19 -> 17850.071 | H20: =Inputs!D4-G20 -> -9050.0707
A21: Tomatoes | B21: 17 | C21: =B21*Inputs!E4*Inputs!$B$10*(1+Inputs!G4)^B21 -> 7733.3395 | D21: =B21*Inputs!D4 -> 149600 | E21: =B21*Inputs!F4 -> 14960 | F21: =MIN(C21,Inputs!$B$13)*Inputs!$B$14+MAX(0,C21-Inputs!$B$13)*Inputs!$B$15 -> 146759.37 | G21: =E21+F21-E20-F20 -> 20265.042 | H21: =Inputs!D4-G21 -> -11465.042
A22: Tomatoes | B22: 18 | C22: =B22*Inputs!E4*Inputs!$B$10*(1+Inputs!G4)^B22 -> 9007.066 | D22: =B22*Inputs!D4 -> 158400 | E22: =B22*Inputs!F4 -> 15840 | F22: =MIN(C22,Inputs!$B$13)*Inputs!$B$14+MAX(0,C22-Inputs!$B$13)*Inputs!$B$15 -> 168872.67 | G22: =E22+F22-E21-F21 -> 22993.307 | H22: =Inputs!D4-G22 -> -14193.307
A23: Tomatoes | B23: 19 | C23: =B23*Inputs!E4*Inputs!$B$10*(1+Inputs!G4)^B23 -> 10458.204 | D23: =B23*Inputs!D4 -> 167200 | E23: =B23*Inputs!F4 -> 16720 | F23: =MIN(C23,Inputs!$B$13)*Inputs!$B$14+MAX(0,C23-Inputs!$B$13)*Inputs!$B$15 -> 194066.05 | G23: =E23+F23-E22-F22 -> 26073.375 | H23: =Inputs!D4-G23 -> -17273.375
A24: Tomatoes | B24: 20 | C24: =B24*Inputs!E4*Inputs!$B$10*(1+Inputs!G4)^B24 -> 12109.5 | D24: =B24*Inputs!D4 -> 176000 | E24: =B24*Inputs!F4 -> 17600 | F24: =MIN(C24,Inputs!$B$13)*Inputs!$B$14+MAX(0,C24-Inputs!$B$13)*Inputs!$B$15 -> 222734.37 | G24: =E24+F24-E23-F23 -> 29548.324 | H24: =Inputs!D4-G24 -> -20748.324
A37: Carrots | B37: 0 | C37: =B37*Inputs!E5*Inputs!$B$10*(1+Inputs!G5)^B37 -> 0 | D37: =B37*Inputs!D5 -> 0 | E37: =B37*Inputs!F5 -> 0 | F37: =MIN(C37,Inputs!$B$13)*Inputs!$B$14+MAX(0,C37-Inputs!$B$13)*Inputs!$B$15 -> 0
A38: Carrots | B38: 1 | C38: =B38*Inputs!E5*Inputs!$B$10*(1+Inputs!G5)^B38 -> 30.75 | D38: =B38*Inputs!D5 -> 2094 | E38: =B38*Inputs!F5 -> 440 | F38: =MIN(C38,Inputs!$B$13)*Inputs!$B$14+MAX(0,C38-Inputs!$B$13)*Inputs!$B$15 -> 1067.7083 | G38: =E38+F38-E37-F37 -> 1507.7083 | H38: =Inputs!D5-G38 -> 586.29167
A39: Carrots | B39: 2 | C39: =B39*Inputs!E5*Inputs!$B$10*(1+Inputs!G5)^B39 -> 63.0375 | D39: =B39*Inputs!D5 -> 4188 | E39: =B39*Inputs!F5 -> 880 | F39: =MIN(C39,Inputs!$B$13)*Inputs!$B$14+MAX(0,C39-Inputs!$B$13)*Inputs!$B$15 -> 2188.8021 | G39: =E39+F39-E38-F38 -> 1561.0937 | H39: =Inputs!D5-G39 -> 532.90625
A40: Carrots | B40: 3 | C40: =B40*Inputs!E5*Inputs!$B$10*(1+Inputs!G5)^B40 -> 96.920156 | D40: =B40*Inputs!D5 -> 6282 | E40: =B40*Inputs!F5 -> 1320 | F40: =MIN(C40,Inputs!$B$13)*Inputs!$B$14+MAX(0,C40-Inputs!$B$13)*Inputs!$B$15 -> 3365.2832 | G40: =E40+F40-E39-F39 -> 1616.4811 | H40: =Inputs!D5-G40 -> 477.51888
A41: Carrots | B41: 4 | C41: =B41*Inputs!E5*Inputs!$B$10*(1+Inputs!G5)^B41 -> 132.45755 | D41: =B41*Inputs!D5 -> 8376 | E41: =B41*Inputs!F5 -> 1760 | F41: =MIN(C41,Inputs!$B$13)*Inputs!$B$14+MAX(0,C41-Inputs!$B$13)*Inputs!$B$15 -> 4599.2204 | G41: =E41+F41-E40-F40 -> 1673.9372 | H41: =Inputs!D5-G41 -> 420.06283
A42: Carrots | B42: 5 | C42: =B42*Inputs!E5*Inputs!$B$10*(1+Inputs!G5)^B42 -> 169.71123 | D42: =B42*Inputs!D5 -> 10470 | E42: =B42*Inputs!F5 -> 2200 | F42: =MIN(C42,Inputs!$B$13)*Inputs!$B$14+MAX(0,C42-Inputs!$B$13)*Inputs!$B$15 -> 5892.7511 | G42: =E42+F42-E41-F41 -> 1733.5307 | H42: =Inputs!D5-G42 -> 360.46927
A43: Carrots | B43: 6 | C43: =B43*Inputs!E5*Inputs!$B$10*(1+Inputs!G5)^B43 -> 208.74482 | D43: =B43*Inputs!D5 -> 12564 | E43: =B43*Inputs!F5 -> 2640 | F43: =MIN(C43,Inputs!$B$13)*Inputs!$B$14+MAX(0,C43-Inputs!$B$13)*Inputs!$B$15 -> 7248.0839 | G43: =E43+F43-E42-F42 -> 1795.3328 | H43: =Inputs!D5-G43 -> 298.66724
A44: Carrots | B44: 7 | C44: =B44*Inputs!E5*Inputs!$B$10*(1+Inputs!G5)^B44 -> 249.62401 | D44: =B44*Inputs!D5 -> 14658 | E44: =B44*Inputs!F5 -> 3080 | F44: =MIN(C44,Inputs!$B$13)*Inputs!$B$14+MAX(0,C44-Inputs!$B$13)*Inputs!$B$15 -> 8667.5003 | G44: =E44+F44-E43-F43 -> 1859.4164 | H44: =Inputs!D5-G44 -> 234.58358
A45: Carrots | B45: 8 | C45: =B45*Inputs!E5*Inputs!$B$10*(1+Inputs!G5)^B45 -> 292.4167 | D45: =B45*Inputs!D5 -> 16752 | E45: =B45*Inputs!F5 -> 3520 | F45: =MIN(C45,Inputs!$B$13)*Inputs!$B$14+MAX(0,C45-Inputs!$B$13)*Inputs!$B$15 -> 10153.357 | G45: =E45+F45-E44-F44 -> 1925.8572 | H45: =Inputs!D5-G45 -> 168.14281
A46: Carrots | B46: 9 | C46: =B46*Inputs!E5*Inputs!$B$10*(1+Inputs!G5)^B46 -> 337.193 | D46: =B46*Inputs!D5 -> 18846 | E46: =B46*Inputs!F5 -> 3960 | F46: =MIN(C46,Inputs!$B$13)*Inputs!$B$14+MAX(0,C46-Inputs!$B$13)*Inputs!$B$15 -> 11708.09 | G46: =E46+F46-E45-F45 -> 1994.7329 | H46: =Inputs!D5-G46 -> 99.267136
A47: Carrots | B47: 10 | C47: =B47*Inputs!E5*Inputs!$B$10*(1+Inputs!G5)^B47 -> 384.02536 | D47: =B47*Inputs!D5 -> 20940 | E47: =B47*Inputs!F5 -> 4400 | F47: =MIN(C47,Inputs!$B$13)*Inputs!$B$14+MAX(0,C47-Inputs!$B$13)*Inputs!$B$15 -> 13334.214 | G47: =E47+F47-E46-F46 -> 2066.1237 | H47: =Inputs!D5-G47 -> 27.876341
A48: Carrots | B48: 11 | C48: =B48*Inputs!E5*Inputs!$B$10*(1+Inputs!G5)^B48 -> 432.9886 | D48: =B48*Inputs!D5 -> 23034 | E48: =B48*Inputs!F5 -> 4840 | F48: =MIN(C48,Inputs!$B$13)*Inputs!$B$14+MAX(0,C48-Inputs!$B$13)*Inputs!$B$15 -> 15034.326 | G48: =E48+F48-E47-F47 -> 2140.1123 | H48: =Inputs!D5-G48 -> -46.112285
A49: Carrots | B49: 12 | C49: =B49*Inputs!E5*Inputs!$B$10*(1+Inputs!G5)^B49 -> 484.15998 | D49: =B49*Inputs!D5 -> 25128 | E49: =B49*Inputs!F5 -> 5280 | F49: =MIN(C49,Inputs!$B$13)*Inputs!$B$14+MAX(0,C49-Inputs!$B$13)*Inputs!$B$15 -> 16811.11 | G49: =E49+F49-E48-F48 -> 2216.784 | H49: =Inputs!D5-G49 -> -122.78402
A50: Carrots | B50: 13 | C50: =B50*Inputs!E5*Inputs!$B$10*(1+Inputs!G5)^B50 -> 537.61931 | D50: =B50*Inputs!D5 -> 27222 | E50: =B50*Inputs!F5 -> 5720 | F50: =MIN(C50,Inputs!$B$13)*Inputs!$B$14+MAX(0,C50-Inputs!$B$13)*Inputs!$B$15 -> 18667.337 | G50: =E50+F50-E49-F49 -> 2296.2268 | H50: =Inputs!D5-G50 -> -202.22676
A51: Carrots | B51: 14 | C51: =B51*Inputs!E5*Inputs!$B$10*(1+Inputs!G5)^B51 -> 593.449 | D51: =B51*Inputs!D5 -> 29316 | E51: =B51*Inputs!F5 -> 6160 | F51: =MIN(C51,Inputs!$B$13)*Inputs!$B$14+MAX(0,C51-Inputs!$B$13)*Inputs!$B$15 -> 20605.868 | G51: =E51+F51-E50-F50 -> 2378.5312 | H51: =Inputs!D5-G51 -> -284.53116
A52: Carrots | B52: 15 | C52: =B52*Inputs!E5*Inputs!$B$10*(1+Inputs!G5)^B52 -> 651.73417 | D52: =B52*Inputs!D5 -> 31410 | E52: =B52*Inputs!F5 -> 6600 | F52: =MIN(C52,Inputs!$B$13)*Inputs!$B$14+MAX(0,C52-Inputs!$B$13)*Inputs!$B$15 -> 22629.659 | G52: =E52+F52-E51-F51 -> 2463.7906 | H52: =Inputs!D5-G52 -> -369.79063
A53: Carrots | B53: 16 | C53: =B53*Inputs!E5*Inputs!$B$10*(1+Inputs!G5)^B53 -> 712.5627 | D53: =B53*Inputs!D5 -> 33504 | E53: =B53*Inputs!F5 -> 7040 | F53: =MIN(C53,Inputs!$B$13)*Inputs!$B$14+MAX(0,C53-Inputs!$B$13)*Inputs!$B$15 -> 24741.76 | G53: =E53+F53-E52-F52 -> 2552.1015 | H53: =Inputs!D5-G53 -> -458.10149
...

Sheet Optimization
A1: FARM MODEL | OPTIMIZATION
A3: Decision variable | B3: Beds
A4: Tomatoes | B4: =Inputs!B4 -> 10.004049
A5: Carrots | B5: =Inputs!B5 -> 20
A6: Mesclun | B6: =Inputs!B6 -> 30
A8: Season profit ($) | B8: ='Cost Structure'!B19 -> 42761.674
A9: Total beds | B9: ='Cost Structure'!B8 -> 60.004049
A10: Total labor hours | B10: ='Cost Structure'!B11 -> 5279.0627
A11: Beds available | B11: =Inputs!B12 -> 64
A12: Labor available | B12: ='Cost Structure'!B20 -> 6480
A13: Beds remaining | B13: =B11-B9 -> 3.995951
A14: Labor remaining | B14: =B12-B10 -> 1200.9373
A15: Crop caps met | B15: =IF(AND(B4<=Inputs!C4,B5<=Inputs!C5,B6<=Inputs!C6),"PASS","FAIL") -> PASS
A16: Overall feasibility | B16: =IF(AND(B13>=0,B14>=0,B15="PASS",MIN(B4:B6)>=0),"FEASIBLE","INFEASIBLE") -> FEASIBLE
A19: Solver objective: Cost Structure!B19 (maximize)
A20: Changing cells: Inputs!B4:B6
A21: Constraints: total beds <=64; labor <=6480; crop caps; nonnegative integers
A22: Use GRG Nonlinear, test starts 0/0/0 and 20/0/0; record results in Audit.

Sheet Audit
A1: FARM MODEL | AUDIT
A3: Check | B3: Formula result | C3: Expected / interpretation
A4: One tomato bed hours | B4: ='Marginal Cost'!C5 -> 99 | C4: 99 hours
A5: Original hypothesis labor (18/18/25) | B5: ='Cost Structure'!B11 -> 5279.0627 | C5: Compare to ~11,384 only when inputs 18/18/25
A6: Available labor | B6: ='Cost Structure'!B20 -> 6480 | C6: 6,480 hours
A7: Labor shortfall | B7: =MAX(0,'Cost Structure'!B11-'Cost Structure'!B20) -> 0 | C7: For original hypothesis, ~4,904 hours
A8: Labor allocation balance | B8: ='Cost Structure'!B24 -> 0 | C8: Zero
A9: Beds feasible | B9: =IF(Optimization!B13>=0,"PASS","FAIL") -> PASS | C9: PASS
A10: Labor feasible | B10: =IF(Optimization!B14>=0,"PASS","FAIL") -> PASS | C10: PASS
A11: Published optimum comparison | B11: =IF(AND(Inputs!B4=10,Inputs!B5=20,Inputs!B6=30),"MATCH","NOT YET") -> NOT YET | C11: 10/20/30, to be independently tested
A12: Profit versus published target | B12: ='Cost Structure'!B19-42762 -> -0.32596201 | C12: Approximately zero at published optimum
A16: Solver start 0/0/0 | C16: Record observed result after running Solver
A17: Solver start 20/0/0 | C17: Record observed result after running Solver
A18: Farm Profit Lab check | C18: Record independently checked marginal cost
A19: Unexpected MC dip | C19: Inspect tomato marginal cost near 6 beds
A20: Audit conclusion | C20: Complete only after running checks
